Workbook

Sheet Dashboard
B2: AgroHouse Foundation (AGHF)
B3: Community Business Sponsorship Dashboard — Program 1: Community Outreach Stabilization
B4: Maintained by: Susan Slater | Updated automatically from the Prospect Tracker tab
B6: KEY METRICS
B7: Total Businesses Identified | F7: =COUNTA('Prospect Tracker'!B7:B1000) -> 71
B8: Total Businesses Contacted | F8: =COUNTIFS('Prospect Tracker'!N7:N1000,"<>Not Contacted",'Prospect Tracker'!N7:N1000,"<>Researching",'Prospect Tracker'!N7:N1000,"<>Contact Information Needed",'Prospect Tracker'!N7:N1000,"<>") -> 0
B9: Total Follow-Ups Due (next 7 days) | F9: =COUNTIFS('Prospect Tracker'!Q7:Q1000,">="&TODAY(),'Prospect Tracker'!Q7:Q1000,"<="&TODAY()+7) -> 0
B10: Meetings Scheduled | F10: =COUNTIF('Prospect Tracker'!S7:S1000,"Yes") -> 0
B11: Sponsorships Approved | F11: =COUNTIF('Prospect Tracker'!N7:N1000,"Sponsorship Approved") -> 0
B12: Sponsorship Revenue Secured | F12: =SUM('Prospect Tracker'!R7:R1000) -> 0
B13: In-Kind Donations Secured | F13: =COUNTIF('Prospect Tracker'!N7:N1000,"In-Kind Donation Received") -> 0
B14: Active Community Partners | F14: =COUNTIF('Prospect Tracker'!N7:N1000,"Community Partner Established") -> 0
B15: Conversion Rate (Approved ÷ Contacted) | F15: =IFERROR(F11/F8,0) -> 0
B19: TOP BUSINESS CATEGORIES BY RESPONSE RATE
B20: Business Category | C20: # Contacted | D20: # Responded / Engaged | E20: Response Rate
B21: Independent Restaurant | C21: =COUNTIFS('Prospect Tracker'!C7:C1000,B21,'Prospect Tracker'!N7:N1000,"<>Not Contacted",'Prospect Tracker'!N7:N1000,"<>Researching",'Prospect Tracker'!N7:N1000,"<>Contact Information Needed",'Prospect Tracker'!N7:N1000,"<>") -> 0 | D21: =COUNTIFS('Prospect Tracker'!C7:C1000,B21,'Prospect Tracker'!N7:N1000,"Spoke With Contact")+COUNTIFS('Prospect Tracker'!C7:C1000,B21,'Prospect Tracker'!N7:N1000,"Meeting Scheduled")+COUNTIFS('Prospect Tracker'!C7:C1000,B21,'Prospect Tracker'!N7:N1000,"Proposal Sent")+COUNTIFS('Prospect Tracker'!C7:C1000,B21,'Prospect Tracker'!N7:N1000,"Considering Sponsorship")+COUNTIFS('Prospect Tracker'!C7:C1000,B21,'Prospect Tracker'!N7:N1000,"Sponsorship Approved")+COUNTIFS('Prospect Tracker'!C7:C1000,B21,'Prospect Tracker'!N7:N1000,"In-Kind Donation Received")+COUNTIFS('Prospect Tracker'!C7:C1000,B21,'Prospect Tracker'!N7:N1000,"Community Partner Established") -> 0 | E21: =IFERROR(D21/C21,0) -> 0
B22: Coffee Shop | C22: =COUNTIFS('Prospect Tracker'!C7:C1000,B22,'Prospect Tracker'!N7:N1000,"<>Not Contacted",'Prospect Tracker'!N7:N1000,"<>Researching",'Prospect Tracker'!N7:N1000,"<>Contact Information Needed",'Prospect Tracker'!N7:N1000,"<>") -> 0 | D22: =COUNTIFS('Prospect Tracker'!C7:C1000,B22,'Prospect Tracker'!N7:N1000,"Spoke With Contact")+COUNTIFS('Prospect Tracker'!C7:C1000,B22,'Prospect Tracker'!N7:N1000,"Meeting Scheduled")+COUNTIFS('Prospect Tracker'!C7:C1000,B22,'Prospect Tracker'!N7:N1000,"Proposal Sent")+COUNTIFS('Prospect Tracker'!C7:C1000,B22,'Prospect Tracker'!N7:N1000,"Considering Sponsorship")+COUNTIFS('Prospect Tracker'!C7:C1000,B22,'Prospect Tracker'!N7:N1000,"Sponsorship Approved")+COUNTIFS('Prospect Tracker'!C7:C1000,B22,'Prospect Tracker'!N7:N1000,"In-Kind Donation Received")+COUNTIFS('Prospect Tracker'!C7:C1000,B22,'Prospect Tracker'!N7:N1000,"Community Partner Established") -> 0 | E22: =IFERROR(D22/C22,0) -> 0
B23: Realtor / Real Estate Team | C23: =COUNTIFS('Prospect Tracker'!C7:C1000,B23,'Prospect Tracker'!N7:N1000,"<>Not Contacted",'Prospect Tracker'!N7:N1000,"<>Researching",'Prospect Tracker'!N7:N1000,"<>Contact Information Needed",'Prospect Tracker'!N7:N1000,"<>") -> 0 | D23: =COUNTIFS('Prospect Tracker'!C7:C1000,B23,'Prospect Tracker'!N7:N1000,"Spoke With Contact")+COUNTIFS('Prospect Tracker'!C7:C1000,B23,'Prospect Tracker'!N7:N1000,"Meeting Scheduled")+COUNTIFS('Prospect Tracker'!C7:C1000,B23,'Prospect Tracker'!N7:N1000,"Proposal Sent")+COUNTIFS('Prospect Tracker'!C7:C1000,B23,'Prospect Tracker'!N7:N1000,"Considering Sponsorship")+COUNTIFS('Prospect Tracker'!C7:C1000,B23,'Prospect Tracker'!N7:N1000,"Sponsorship Approved")+COUNTIFS('Prospect Tracker'!C7:C1000,B23,'Prospect Tracker'!N7:N1000,"In-Kind Donation Received")+COUNTIFS('Prospect Tracker'!C7:C1000,B23,'Prospect Tracker'!N7:N1000,"Community Partner Established") -> 0 | E23: =IFERROR(D23/C23,0) -> 0
B24: Insurance Agency | C24: =COUNTIFS('Prospect Tracker'!C7:C1000,B24,'Prospect Tracker'!N7:N1000,"<>Not Contacted",'Prospect Tracker'!N7:N1000,"<>Researching",'Prospect Tracker'!N7:N1000,"<>Contact Information Needed",'Prospect Tracker'!N7:N1000,"<>") -> 0 | D24: =COUNTIFS('Prospect Tracker'!C7:C1000,B24,'Prospect Tracker'!N7:N1000,"Spoke With Contact")+COUNTIFS('Prospect Tracker'!C7:C1000,B24,'Prospect Tracker'!N7:N1000,"Meeting Scheduled")+COUNTIFS('Prospect Tracker'!C7:C1000,B24,'Prospect Tracker'!N7:N1000,"Proposal Sent")+COUNTIFS('Prospect Tracker'!C7:C1000,B24,'Prospect Tracker'!N7:N1000,"Considering Sponsorship")+COUNTIFS('Prospect Tracker'!C7:C1000,B24,'Prospect Tracker'!N7:N1000,"Sponsorship Approved")+COUNTIFS('Prospect Tracker'!C7:C1000,B24,'Prospect Tracker'!N7:N1000,"In-Kind Donation Received")+COUNTIFS('Prospect Tracker'!C7:C1000,B24,'Prospect Tracker'!N7:N1000,"Community Partner Established") -> 0 | E24: =IFERROR(D24/C24,0) -> 0
B25: Mortgage Broker | C25: =COUNTIFS('Prospect Tracker'!C7:C1000,B25,'Prospect Tracker'!N7:N1000,"<>Not Contacted",'Prospect Tracker'!N7:N1000,"<>Researching",'Prospect Tracker'!N7:N1000,"<>Contact Information Needed",'Prospect Tracker'!N7:N1000,"<>") -> 0 | D25: =COUNTIFS('Prospect Tracker'!C7:C1000,B25,'Prospect Tracker'!N7:N1000,"Spoke With Contact")+COUNTIFS('Prospect Tracker'!C7:C1000,B25,'Prospect Tracker'!N7:N1000,"Meeting Scheduled")+COUNTIFS('Prospect Tracker'!C7:C1000,B25,'Prospect Tracker'!N7:N1000,"Proposal Sent")+COUNTIFS('Prospect Tracker'!C7:C1000,B25,'Prospect Tracker'!N7:N1000,"Considering Sponsorship")+COUNTIFS('Prospect Tracker'!C7:C1000,B25,'Prospect Tracker'!N7:N1000,"Sponsorship Approved")+COUNTIFS('Prospect Tracker'!C7:C1000,B25,'Prospect Tracker'!N7:N1000,"In-Kind Donation Received")+COUNTIFS('Prospect Tracker'!C7:C1000,B25,'Prospect Tracker'!N7:N1000,"Community Partner Established") -> 0 | E25: =IFERROR(D25/C25,0) -> 0
B26: Title Company | C26: =COUNTIFS('Prospect Tracker'!C7:C1000,B26,'Prospect Tracker'!N7:N1000,"<>Not Contacted",'Prospect Tracker'!N7:N1000,"<>Researching",'Prospect Tracker'!N7:N1000,"<>Contact Information Needed",'Prospect Tracker'!N7:N1000,"<>") -> 0 | D26: =COUNTIFS('Prospect Tracker'!C7:C1000,B26,'Prospect Tracker'!N7:N1000,"Spoke With Contact")+COUNTIFS('Prospect Tracker'!C7:C1000,B26,'Prospect Tracker'!N7:N1000,"Meeting Scheduled")+COUNTIFS('Prospect Tracker'!C7:C1000,B26,'Prospect Tracker'!N7:N1000,"Proposal Sent")+COUNTIFS('Prospect Tracker'!C7:C1000,B26,'Prospect Tracker'!N7:N1000,"Considering Sponsorship")+COUNTIFS('Prospect Tracker'!C7:C1000,B26,'Prospect Tracker'!N7:N1000,"Sponsorship Approved")+COUNTIFS('Prospect Tracker'!C7:C1000,B26,'Prospect Tracker'!N7:N1000,"In-Kind Donation Received")+COUNTIFS('Prospect Tracker'!C7:C1000,B26,'Prospect Tracker'!N7:N1000,"Community Partner Established") -> 0 | E26: =IFERROR(D26/C26,0) -> 0
B27: HVAC Contractor | C27: =COUNTIFS('Prospect Tracker'!C7:C1000,B27,'Prospect Tracker'!N7:N1000,"<>Not Contacted",'Prospect Tracker'!N7:N1000,"<>Researching",'Prospect Tracker'!N7:N1000,"<>Contact Information Needed",'Prospect Tracker'!N7:N1000,"<>") -> 0 | D27: =COUNTIFS('Prospect Tracker'!C7:C1000,B27,'Prospect Tracker'!N7:N1000,"Spoke With Contact")+COUNTIFS('Prospect Tracker'!C7:C1000,B27,'Prospect Tracker'!N7:N1000,"Meeting Scheduled")+COUNTIFS('Prospect Tracker'!C7:C1000,B27,'Prospect Tracker'!N7:N1000,"Proposal Sent")+COUNTIFS('Prospect Tracker'!C7:C1000,B27,'Prospect Tracker'!N7:N1000,"Considering Sponsorship")+COUNTIFS('Prospect Tracker'!C7:C1000,B27,'Prospect Tracker'!N7:N1000,"Sponsorship Approved")+COUNTIFS('Prospect Tracker'!C7:C1000,B27,'Prospect Tracker'!N7:N1000,"In-Kind Donation Received")+COUNTIFS('Prospect Tracker'!C7:C1000,B27,'Prospect Tracker'!N7:N1000,"Community Partner Established") -> 0 | E27: =IFERROR(D27/C27,0) -> 0
B28: Plumber | C28: =COUNTIFS('Prospect Tracker'!C7:C1000,B28,'Prospect Tracker'!N7:N1000,"<>Not Contacted",'Prospect Tracker'!N7:N1000,"<>Researching",'Prospect Tracker'!N7:N1000,"<>Contact Information Needed",'Prospect Tracker'!N7:N1000,"<>") -> 0 | D28: =COUNTIFS('Prospect Tracker'!C7:C1000,B28,'Prospect Tracker'!N7:N1000,"Spoke With Contact")+COUNTIFS('Prospect Tracker'!C7:C1000,B28,'Prospect Tracker'!N7:N1000,"Meeting Scheduled")+COUNTIFS('Prospect Tracker'!C7:C1000,B28,'Prospect Tracker'!N7:N1000,"Proposal Sent")+COUNTIFS('Prospect Tracker'!C7:C1000,B28,'Prospect Tracker'!N7:N1000,"Considering Sponsorship")+COUNTIFS('Prospect Tracker'!C7:C1000,B28,'Prospect Tracker'!N7:N1000,"Sponsorship Approved")+COUNTIFS('Prospect Tracker'!C7:C1000,B28,'Prospect Tracker'!N7:N1000,"In-Kind Donation Received")+COUNTIFS('Prospect Tracker'!C7:C1000,B28,'Prospect Tracker'!N7:N1000,"Community Partner Established") -> 0 | E28: =IFERROR(D28/C28,0) -> 0
B29: Electrician | C29: =COUNTIFS('Prospect Tracker'!C7:C1000,B29,'Prospect Tracker'!N7:N1000,"<>Not Contacted",'Prospect Tracker'!N7:N1000,"<>Researching",'Prospect Tracker'!N7:N1000,"<>Contact Information Needed",'Prospect Tracker'!N7:N1000,"<>") -> 0 | D29: =COUNTIFS('Prospect Tracker'!C7:C1000,B29,'Prospect Tracker'!N7:N1000,"Spoke With Contact")+COUNTIFS('Prospect Tracker'!C7:C1000,B29,'Prospect Tracker'!N7:N1000,"Meeting Scheduled")+COUNTIFS('Prospect Tracker'!C7:C1000,B29,'Prospect Tracker'!N7:N1000,"Proposal Sent")+COUNTIFS('Prospect Tracker'!C7:C1000,B29,'Prospect Tracker'!N7:N1000,"Considering Sponsorship")+COUNTIFS('Prospect Tracker'!C7:C1000,B29,'Prospect Tracker'!N7:N1000,"Sponsorship Approved")+COUNTIFS('Prospect Tracker'!C7:C1000,B29,'Prospect Tracker'!N7:N1000,"In-Kind Donation Received")+COUNTIFS('Prospect Tracker'!C7:C1000,B29,'Prospect Tracker'!N7:N1000,"Community Partner Established") -> 0 | E29: =IFERROR(D29/C29,0) -> 0
B30: Roofing Company | C30: =COUNTIFS('Prospect Tracker'!C7:C1000,B30,'Prospect Tracker'!N7:N1000,"<>Not Contacted",'Prospect Tracker'!N7:N1000,"<>Researching",'Prospect Tracker'!N7:N1000,"<>Contact Information Needed",'Prospect Tracker'!N7:N1000,"<>") -> 0 | D30: =COUNTIFS('Prospect Tracker'!C7:C1000,B30,'Prospect Tracker'!N7:N1000,"Spoke With Contact")+COUNTIFS('Prospect Tracker'!C7:C1000,B30,'Prospect Tracker'!N7:N1000,"Meeting Scheduled")+COUNTIFS('Prospect Tracker'!C7:C1000,B30,'Prospect Tracker'!N7:N1000,"Proposal Sent")+COUNTIFS('Prospect Tracker'!C7:C1000,B30,'Prospect Tracker'!N7:N1000,"Considering Sponsorship")+COUNTIFS('Prospect Tracker'!C7:C1000,B30,'Prospect Tracker'!N7:N1000,"Sponsorship Approved")+COUNTIFS('Prospect Tracker'!C7:C1000,B30,'Prospect Tracker'!N7:N1000,"In-Kind Donation Received")+COUNTIFS('Prospect Tracker'!C7:C1000,B30,'Prospect Tracker'!N7:N1000,"Community Partner Established") -> 0 | E30: =IFERROR(D30/C30,0) -> 0
B31: Landscaping Company | C31: =COUNTIFS('Prospect Tracker'!C7:C1000,B31,'Prospect Tracker'!N7:N1000,"<>Not Contacted",'Prospect Tracker'!N7:N1000,"<>Researching",'Prospect Tracker'!N7:N1000,"<>Contact Information Needed",'Prospect Tracker'!N7:N1000,"<>") -> 0 | D31: =COUNTIFS('Prospect Tracker'!C7:C1000,B31,'Prospect Tracker'!N7:N1000,"Spoke With Contact")+COUNTIFS('Prospect Tracker'!C7:C1000,B31,'Prospect Tracker'!N7:N1000,"Meeting Scheduled")+COUNTIFS('Prospect Tracker'!C7:C1000,B31,'Prospect Tracker'!N7:N1000,"Proposal Sent")+COUNTIFS('Prospect Tracker'!C7:C1000,B31,'Prospect Tracker'!N7:N1000,"Considering Sponsorship")+COUNTIFS('Prospect Tracker'!C7:C1000,B31,'Prospect Tracker'!N7:N1000,"Sponsorship Approved")+COUNTIFS('Prospect Tracker'!C7:C1000,B31,'Prospect Tracker'!N7:N1000,"In-Kind Donation Received")+COUNTIFS('Prospect Tracker'!C7:C1000,B31,'Prospect Tracker'!N7:N1000,"Community Partner Established") -> 0 | E31: =IFERROR(D31/C31,0) -> 0
B32: Veterinary Clinic | C32: =COUNTIFS('Prospect Tracker'!C7:C1000,B32,'Prospect Tracker'!N7:N1000,"<>Not Contacted",'Prospect Tracker'!N7:N1000,"<>Researching",'Prospect Tracker'!N7:N1000,"<>Contact Information Needed",'Prospect Tracker'!N7:N1000,"<>") -> 0 | D32: =COUNTIFS('Prospect Tracker'!C7:C1000,B32,'Prospect Tracker'!N7:N1000,"Spoke With Contact")+COUNTIFS('Prospect Tracker'!C7:C1000,B32,'Prospect Tracker'!N7:N1000,"Meeting Scheduled")+COUNTIFS('Prospect Tracker'!C7:C1000,B32,'Prospect Tracker'!N7:N1000,"Proposal Sent")+COUNTIFS('Prospect Tracker'!C7:C1000,B32,'Prospect Tracker'!N7:N1000,"Considering Sponsorship")+COUNTIFS('Prospect Tracker'!C7:C1000,B32,'Prospect Tracker'!N7:N1000,"Sponsorship Approved")+COUNTIFS('Prospect Tracker'!C7:C1000,B32,'Prospect Tracker'!N7:N1000,"In-Kind Donation Received")+COUNTIFS('Prospect Tracker'!C7:C1000,B32,'Prospect Tracker'!N7:N1000,"Community Partner Established") -> 0 | E32: =IFERROR(D32/C32,0) -> 0
B33: Chiropractic Office | C33: =COUNTIFS('Prospect Tracker'!C7:C1000,B33,'Prospect Tracker'!N7:N1000,"<>Not Contacted",'Prospect Tracker'!N7:N1000,"<>Researching",'Prospect Tracker'!N7:N1000,"<>Contact Information Needed",'Prospect Tracker'!N7:N1000,"<>") -> 0 | D33: =COUNTIFS('Prospect Tracker'!C7:C1000,B33,'Prospect Tracker'!N7:N1000,"Spoke With Contact")+COUNTIFS('Prospect Tracker'!C7:C1000,B33,'Prospect Tracker'!N7:N1000,"Meeting Scheduled")+COUNTIFS('Prospect Tracker'!C7:C1000,B33,'Prospect Tracker'!N7:N1000,"Proposal Sent")+COUNTIFS('Prospect Tracker'!C7:C1000,B33,'Prospect Tracker'!N7:N1000,"Considering Sponsorship")+COUNTIFS('Prospect Tracker'!C7:C1000,B33,'Prospect Tracker'!N7:N1000,"Sponsorship Approved")+COUNTIFS('Prospect Tracker'!C7:C1000,B33,'Prospect Tracker'!N7:N1000,"In-Kind Donation Received")+COUNTIFS('Prospect Tracker'!C7:C1000,B33,'Prospect Tracker'!N7:N1000,"Community Partner Established") -> 0 | E33: =IFERROR(D33/C33,0) -> 0
B34: Feed Store | C34: =COUNTIFS('Prospect Tracker'!C7:C1000,B34,'Prospect Tracker'!N7:N1000,"<>Not Contacted",'Prospect Tracker'!N7:N1000,"<>Researching",'Prospect Tracker'!N7:N1000,"<>Contact Information Needed",'Prospect Tracker'!N7:N1000,"<>") -> 0 | D34: =COUNTIFS('Prospect Tracker'!C7:C1000,B34,'Prospect Tracker'!N7:N1000,"Spoke With Contact")+COUNTIFS('Prospect Tracker'!C7:C1000,B34,'Prospect Tracker'!N7:N1000,"Meeting Scheduled")+COUNTIFS('Prospect Tracker'!C7:C1000,B34,'Prospect Tracker'!N7:N1000,"Proposal Sent")+COUNTIFS('Prospect Tracker'!C7:C1000,B34,'Prospect Tracker'!N7:N1000,"Considering Sponsorship")+COUNTIFS('Prospect Tracker'!C7:C1000,B34,'Prospect Tracker'!N7:N1000,"Sponsorship Approved")+COUNTIFS('Prospect Tracker'!C7:C1000,B34,'Prospect Tracker'!N7:N1000,"In-Kind Donation Received")+COUNTIFS('Prospect Tracker'!C7:C1000,B34,'Prospect Tracker'!N7:N1000,"Community Partner Established") -> 0 | E34: =IFERROR(D34/C34,0) -> 0
B35: Nursery / Garden Center | C35: =COUNTIFS('Prospect Tracker'!C7:C1000,B35,'Prospect Tracker'!N7:N1000,"<>Not Contacted",'Prospect Tracker'!N7:N1000,"<>Researching",'Prospect Tracker'!N7:N1000,"<>Contact Information Needed",'Prospect Tracker'!N7:N1000,"<>") -> 0 | D35: =COUNTIFS('Prospect Tracker'!C7:C1000,B35,'Prospect Tracker'!N7:N1000,"Spoke With Contact")+COUNTIFS('Prospect Tracker'!C7:C1000,B35,'Prospect Tracker'!N7:N1000,"Meeting Scheduled")+COUNTIFS('Prospect Tracker'!C7:C1000,B35,'Prospect Tracker'!N7:N1000,"Proposal Sent")+COUNTIFS('Prospect Tracker'!C7:C1000,B35,'Prospect Tracker'!N7:N1000,"Considering Sponsorship")+COUNTIFS('Prospect Tracker'!C7:C1000,B35,'Prospect Tracker'!N7:N1000,"Sponsorship Approved")+COUNTIFS('Prospect Tracker'!C7:C1000,B35,'Prospect Tracker'!N7:N1000,"In-Kind Donation Received")+COUNTIFS('Prospect Tracker'!C7:C1000,B35,'Prospect Tracker'!N7:N1000,"Community Partner Established") -> 0 | E35: =IFERROR(D35/C35,0) -> 0
B36: Farm Supply | C36: =COUNTIFS('Prospect Tracker'!C7:C1000,B36,'Prospect Tracker'!N7:N1000,"<>Not Contacted",'Prospect Tracker'!N7:N1000,"<>Researching",'Prospect Tracker'!N7:N1000,"<>Contact Information Needed",'Prospect Tracker'!N7:N1000,"<>") -> 0 | D36: =COUNTIFS('Prospect Tracker'!C7:C1000,B36,'Prospect Tracker'!N7:N1000,"Spoke With Contact")+COUNTIFS('Prospect Tracker'!C7:C1000,B36,'Prospect Tracker'!N7:N1000,"Meeting Scheduled")+COUNTIFS('Prospect Tracker'!C7:C1000,B36,'Prospect Tracker'!N7:N1000,"Proposal Sent")+COUNTIFS('Prospect Tracker'!C7:C1000,B36,'Prospect Tracker'!N7:N1000,"Considering Sponsorship")+COUNTIFS('Prospect Tracker'!C7:C1000,B36,'Prospect Tracker'!N7:N1000,"Sponsorship Approved")+COUNTIFS('Prospect Tracker'!C7:C1000,B36,'Prospect Tracker'!N7:N1000,"In-Kind Donation Received")+COUNTIFS('Prospect Tracker'!C7:C1000,B36,'Prospect Tracker'!N7:N1000,"Community Partner Established") -> 0 | E36: =IFERROR(D36/C36,0) -> 0
B37: Locally Owned Retail | C37: =COUNTIFS('Prospect Tracker'!C7:C1000,B37,'Prospect Tracker'!N7:N1000,"<>Not Contacted",'Prospect Tracker'!N7:N1000,"<>Researching",'Prospect Tracker'!N7:N1000,"<>Contact Information Needed",'Prospect Tracker'!N7:N1000,"<>") -> 0 | D37: =COUNTIFS('Prospect Tracker'!C7:C1000,B37,'Prospect Tracker'!N7:N1000,"Spoke With Contact")+COUNTIFS('Prospect Tracker'!C7:C1000,B37,'Prospect Tracker'!N7:N1000,"Meeting Scheduled")+COUNTIFS('Prospect Tracker'!C7:C1000,B37,'Prospect Tracker'!N7:N1000,"Proposal Sent")+COUNTIFS('Prospect Tracker'!C7:C1000,B37,'Prospect Tracker'!N7:N1000,"Considering Sponsorship")+COUNTIFS('Prospect Tracker'!C7:C1000,B37,'Prospect Tracker'!N7:N1000,"Sponsorship Approved")+COUNTIFS('Prospect Tracker'!C7:C1000,B37,'Prospect Tracker'!N7:N1000,"In-Kind Donation Received")+COUNTIFS('Prospect Tracker'!C7:C1000,B37,'Prospect Tracker'!N7:N1000,"Community Partner Established") -> 0 | E37: =IFERROR(D37/C37,0) -> 0
B40: Note: This dashboard reads live from the Prospect Tracker tab. Update statuses there and these numbers refresh automatically.

Sheet Dropdown Lists
A1: Outcome Status | B1: Sponsorship Level Discussed | C1: Yes / No | D1: Business Category | E1: City | F1: Assigned To
A2: Not Contacted | B2: Bronze | C2: Yes | D2: Independent Restaurant | E2: Wesley Chapel | F2: Susan Slater
A3: Researching | B3: Silver | C3: No | D3: Coffee Shop | E3: Zephyrhills | F3: Board Member
A4: Contact Information Needed | B4: Gold | D4: Realtor / Real Estate Team | E4: Dade City | F4: Volunteer
A5: Email Sent | B5: Founding Sponsor | D5: Insurance Agency | E5: Land O' Lakes | F5: Unassigned
A6: Voicemail Left | B6: In-Kind Only | D6: Mortgage Broker | E6: East Pasco County (Other)
A7: Spoke With Contact | B7: Not Yet Discussed | D7: Title Company
A8: Follow-Up Required | D8: HVAC Contractor
A9: Meeting Scheduled | D9: Plumber
A10: Proposal Sent | D10: Electrician
A11: Considering Sponsorship | D11: Roofing Company
A12: Interested for Future | D12: Landscaping Company
A13: Sponsorship Approved | D13: Veterinary Clinic
A14: Sponsorship Declined | D14: Chiropractic Office
A15: In-Kind Donation Received | D15: Feed Store
A16: Community Partner Established | D16: Nursery / Garden Center
A17: No Response | D17: Farm Supply
A18: Do Not Contact | D18: Locally Owned Retail
D19: Other

Sheet Prospect Tracker
A2: AgroHouse Foundation — Local Business Sponsorship Prospect Tracker
A3: Program 1: Community Outreach Stabilization | Wesley Chapel · Zephyrhills · Dade City · Land O' Lakes · East Pasco County
A4: Legend: Yellow-filled cells are starter data already researched. White cells are for Susan/the team to fill in as outreach progresses (contact name, dates, notes, etc.).
A6: Business ID Number | B6: Business Name | C6: Business Category | D6: City | E6: Contact Name | F6: Phone Number | G6: Email Address | H6: Website | I6: Facebook Page | J6: Date Added | K6: Initial Contact Date | L6: Follow-Up Date | M6: Second Follow-Up Date | N6: Outcome Status | O6: Sponsorship Level Discussed | P6: Sponsorship Amount Requested | Q6: Sponsorship Amount Committed | R6: In-Kind Donation Offered | S6: Meeting Scheduled (Yes/No) | T6: Proposal Sent (Yes/No) | U6: Decision Date | V6: Notes | W6: Next Action Required | X6: Assigned To | Y6: Prospect Score (1-10)
A7: AGHF-001 | B7: The Living Room of Wesley Chapel | C7: Independent Restaurant | D7: Wesley Chapel | E7: Zach or Christina Feinstein | F7: 813-934-7911 | G7: social@tlr.restaurant | N7: Not Contacted | O7: Not Yet Discussed | S7: No | T7: No | W7: Research contact name/email; place initial call or visit | X7: Susan Slater | Y7: 6
A8: AGHF-002 | B8: La Creación Bistro | C8: Independent Restaurant | D8: Wesley Chapel | E8: Armando Torres or Ramon Ruiz | F8: 813-388-5872 | G8: lacreacionbakery@gmail.com | N8: Not Contacted | O8: Not Yet Discussed | S8: No | T8: No | W8: Research contact name/email; place initial call or visit | X8: Susan Slater | Y8: 7
A9: AGHF-003 | B9: Noble Crust of Wesley Chapel | C9: Independent Restaurant | D9: Wesley Chapel | E9: TJ Thielbar, Jeff Strouse, Tim Curci | F9: 813-703-2602 | G9: info@noble-crust.com | N9: Not Contacted | O9: Not Yet Discussed | S9: No | T9: No | W9: Research contact name/email; place initial call or visit | X9: Susan Slater | Y9: 6
A10: AGHF-004 | B10: Tallo Restaurant & Bar | C10: Independent Restaurant | D10: Wesley Chapel | E10: Ramon Ruiz or Kelvin Cruz | F10: 813-355-3603 | G10: info@tallorestaurant.com | H10: https://tallorestaurant.com/ | I10: https://www.facebook.com/profile.php?id=61561779217810# | N10: Not Contacted | O10: Not Yet Discussed | S10: No | T10: No | W10: Research contact name/email; place initial call or visit | X10: Susan Slater | Y10: 6
A11: AGHF-005 | B11: 1916 Irish Pub Wesley Chapel | C11: Independent Restaurant | D11: Wesley Chapel | E11: Chuck Jamieson | F11: 813-991-4747 | G11: Chuck.1916pub@gmail.com | H11: https://1916irishpub.com/ | N11: Not Contacted | O11: Not Yet Discussed | S11: No | T11: No | W11: Research contact name/email; place initial call or visit | X11: Susan Slater | Y11: 6
A12: AGHF-006 | B12: Tina & Joe's Cafe | C12: Independent Restaurant | D12: Zephyrhills | E12: Tina or Joe Novak | F12: 352-521-3051 | G12: tinajoescafe@gmail.com | I12: https://www.facebook.com/TinaJoeCafe/ | N12: Not Contacted | O12: Not Yet Discussed | S12: No | T12: No | W12: Research contact name/email; place initial call or visit | X12: Susan Slater | Y12: 7
A13: AGHF-007 | B13: The Farmhouse Market & Café | C13: Independent Restaurant | D13: Dade City | E13: Ronnie or Jenny Williams | F13: 352-437-5995 | G13: farmhousemarketcafe@gmail.com | H13: www.myfarmhousemarket.com | N13: Not Contacted | O13: Not Yet Discussed | S13: No | T13: No | W13: Research contact name/email; place initial call or visit | X13: Susan Slater | Y13: 8
A14: AGHF-008 | B14: Healthy Vibes Cafe | C14: Independent Restaurant | D14: Zephyrhills | E14: Aaron Ringer | F14: 301-752-9865 | G14: N/A | N14: Not Contacted | O14: Not Yet Discussed | S14: No | T14: No | W14: Research contact name/email; place initial call or visit | X14: Susan Slater | Y14: 7
A15: AGHF-009 | B15: The Original Floridian Bar & Grill | C15: Independent Restaurant | D15: Dade City | E15: Blair or Ethan Hensley | F15: 352-668-4064 | G15: N/A | N15: Not Contacted | O15: Not Yet Discussed | S15: No | T15: No | W15: Research contact name/email; place initial call or visit | X15: Susan Slater | Y15: 6
A16: AGHF-010 | B16: The Roost Market Cafe | C16: Independent Restaurant | D16: Dade City | E16: Joseph Piazza | F16: 352-437-3055 | G16: admin@piazzahg.com | N16: Not Contacted | O16: Not Yet Discussed | S16: No | T16: No | W16: Research contact name/email; place initial call or visit | X16: Susan Slater | Y16: 7
A17: AGHF-011 | B17: Olio | C17: Independent Restaurant | D17: Dade City | E17: N/A | F17: 352-437-3892 | G17: N/A | N17: Not Contacted | O17: Not Yet Discussed | S17: No | T17: No | W17: Research contact name/email; place initial call or visit | X17: Susan Slater | Y17: 6
A18: AGHF-012 | B18: Le Garden Bistro | C18: Independent Restaurant | D18: Dade City | E18: Wanderson Dearaujo | F18: 352-437-3721 | N18: Not Contacted | O18: Not Yet Discussed | S18: No | T18: No | W18: Research contact name/email; place initial call or visit | X18: Susan Slater | Y18: 6
A19: AGHF-013 | B19: SR 54 Coffee & Tea Co | C19: Coffee Shop | D19: Zephyrhills | E19: Endrias Bekele | F19: 813-782-3775 | N19: Not Contacted | O19: Not Yet Discussed | S19: No | T19: No | W19: Research contact name/email; place initial call or visit | X19: Susan Slater | Y19: 8
A20: AGHF-014 | B20: Pámpano Coffee | C20: Coffee Shop | D20: Zephyrhills | E20: Shaila or Jonathan Thomas | F20: 813-516-6889 | N20: Not Contacted | O20: Not Yet Discussed | S20: No | T20: No | W20: Research contact name/email; place initial call or visit | X20: Susan Slater | Y20: 8
A21: AGHF-015 | B21: Babe Coffee Lounge | C21: Coffee Shop | D21: Land O' Lakes | E21: Bridgette Vital | F21: 813-723-2223 | N21: Not Contacted | O21: Not Yet Discussed | S21: No | T21: No | W21: Research contact name/email; place initial call or visit | X21: Susan Slater | Y21: 7
A22: AGHF-016 | B22: Empire Coffee & Deli | C22: Coffee Shop | D22: Land O' Lakes | E22: Jessica Francisco | F22: 727-601-7816 | N22: Not Contacted | O22: Not Yet Discussed | S22: No | T22: No | W22: Research contact name/email; place initial call or visit | X22: Susan Slater | Y22: 8
A23: AGHF-017 | B23: Urban Crunch Creamery Cafe - Bexley | C23: Coffee Shop | D23: Land O' Lakes | E23: Kyrsten Sabb | F23: 813-647-8618 | N23: Not Contacted | O23: Not Yet Discussed | S23: No | T23: No | W23: Research contact name/email; place initial call or visit | X23: Susan Slater | Y23: 7
A24: AGHF-018 | B24: Cotee River Creamery & Desserts | C24: Coffee Shop | D24: Land O' Lakes | E24: George or Shelly Stacy | F24: 352-242-7093 | N24: Not Contacted | O24: Not Yet Discussed | S24: No | T24: No | W24: Research contact name/email; place initial call or visit | X24: Susan Slater | Y24: 7
A25: AGHF-019 | B25: 54 Realty | C25: Realtor / Real Estate Team | D25: Land O' Lakes | E25: Joseph LoCicero | F25: 813-435-5411 | N25: Not Contacted | O25: Not Yet Discussed | S25: No | T25: No | W25: Research contact name/email; place initial call or visit | X25: Susan Slater | Y25: 7
A26: AGHF-020 | B26: 1 Percent Lists Central Florida | C26: Realtor / Real Estate Team | D26: Land O' Lakes | E26: Mike Del Grande | F26: 727-967-9779 | N26: Not Contacted | O26: Not Yet Discussed | S26: No | T26: No | W26: Research contact name/email; place initial call or visit | X26: Susan Slater | Y26: 6
A27: AGHF-021 | B27: First Integrity Real Estate LLC | C27: Realtor / Real Estate Team | D27: Land O' Lakes | E27: Adam or Michael Jonas | F27: 813-922-1565 | N27: Not Contacted | O27: Not Yet Discussed | S27: No | T27: No | W27: Research contact name/email; place initial call or visit | X27: Susan Slater | Y27: 7
A28: AGHF-022 | B28: Tampa Bay Home Team | C28: Realtor / Real Estate Team | D28: Wesley Chapel | E28: Joseph or Christina Kipping | F28: 813-321-4663 | N28: Not Contacted | O28: Not Yet Discussed | S28: No | T28: No | W28: Research contact name/email; place initial call or visit | X28: Susan Slater | Y28: 7
A29: AGHF-023 | B29: Yvette Fuertes REALTOR – Art Of Realty Group | C29: Realtor / Real Estate Team | D29: Wesley Chapel | E29: Yvette Fuertes | F29: 813-310-9462 | N29: Not Contacted | O29: Not Yet Discussed | S29: No | T29: No | W29: Research contact name/email; place initial call or visit | X29: Susan Slater | Y29: 7
... A77: AGHF-071 | B77: E & Emagine | C77: Locally Owned Retail | D77: Zephyrhills | E77: Eppie, Emmalise Feliciano | F77: 813-862-7551 | N77: Not Contacted | O77: Not Yet Discussed | S77: No | T77: No | W77: Research contact name/email; place initial call or visit | X77: Susan Slater | Y77: 8
A78: AGHF-072 | N78: Not Contacted | O78: Not Yet Discussed | S78: No | T78: No | X78: Susan Slater
A79: AGHF-073 | N79: Not Contacted | O79: Not Yet Discussed | S79: No | T79: No | X79: Susan Slater
A80: AGHF-074 | N80: Not Contacted | O80: Not Yet Discussed | S80: No | T80: No | X80: Susan Slater
A81: AGHF-075 | N81: Not Contacted | O81: Not Yet Discussed | S81: No | T81: No | X81: Susan Slater
A82: AGHF-076 | N82: Not Contacted | O82: Not Yet Discussed | S82: No | T82: No | X82: Susan Slater
A83: AGHF-077 | N83: Not Contacted | O83: Not Yet Discussed | S83: No | T83: No | X83: Susan Slater
A84: AGHF-078 | N84: Not Contacted | O84: Not Yet Discussed | S84: No | T84: No | X84: Susan Slater
A85: AGHF-079 | N85: Not Contacted | O85: Not Yet Discussed | S85: No | T85: No | X85: Susan Slater
A86: AGHF-080 | N86: Not Contacted | O86: Not Yet Discussed | S86: No | T86: No | X86: Susan Slater
A87: AGHF-081 | N87: Not Contacted | O87: Not Yet Discussed | S87: No | T87: No | X87: Susan Slater
A88: AGHF-082 | N88: Not Contacted | O88: Not Yet Discussed | S88: No | T88: No | X88: Susan Slater
A89: AGHF-083 | N89: Not Contacted | O89: Not Yet Discussed | S89: No | T89: No | X89: Susan Slater
...

Sheet Scoring & Workflow Guide
B2: Prospect Scoring System (1–10)
B4: Score | C4: Meaning | D4: Typical Signals
B5: 9–10 | C5: High-priority, warm relationship | D5: Existing personal/board connection; business owner known to AGHF team; strong local reputation; visible community involvement
B6: 7–8 | C6: Strong fit, cold but promising | D6: Independently owned; active on Facebook/Instagram in the community; located directly in target service area; already sponsors local events/schools
B7: 5–6 | C7: Reasonable fit, needs relationship-building | D7: Independently owned but no known connection yet; average online engagement; general community-facing business
B8: 3–4 | C8: Lower priority for now | D8: Very small operation with limited marketing budget; inconsistent hours/contact info; unclear decision-maker
B9: 1–2 | C9: Not a good current fit | D9: Franchise/chain requiring corporate approval; no local decision-making authority; unresponsive after multiple attempts
B12: Contact Prioritization Method
B13: 1. Sort the Prospect Tracker by Prospect Score (descending), then by City to batch outreach efficiently by geography.
B14: 2. Contact scores of 8–10 first — these convert fastest and build early momentum and referenceable success stories.
B15: 3. Work scores of 5–7 in the same visit/call block as nearby 8–10 prospects (e.g., same shopping plaza or corridor).
B16: 4. Revisit scores of 1–4 only after the initial 90-day cycle, or if a warm introduction becomes available.
B17: 5. Re-score any business after first contact based on actual receptiveness — scores are living estimates, not fixed labels.
B19: Sponsorship Pipeline Workflow
B20: Researching → Contact Information Needed → Email Sent / Voicemail Left → Spoke With Contact →
B21: Meeting Scheduled → Proposal Sent → Considering Sponsorship → Sponsorship Approved / Declined →
B22: In-Kind Donation Received (if applicable) → Community Partner Established (renewal relationship)
